Workbook

Sheet Cover
B2: ATHER ENERGY LIMITED
B3: Integrated Financial Model & DCF Valuation
B4: History FY2021-FY2025 | Forecast FY2026E-FY2033E | INR millions | Standalone (consolidated-equivalent)
B6: Contents | E6: Headline outputs (Base case)
B7: Scenarios | C7: Base / Bull / Bear switch — volume growth & gross margin | E7: FY2025 revenue (INR m) | H7: =PL!G5
B8: Assumptions | C8: All macro, industry & company drivers with source + reason | E8: FY2033E revenue (INR m) | H8: =PL!O5
B9: Revenue Build | C9: Driver-based revenue (volume x ASP + accessories/software/charging/service) | E9: FY2025 EBITDA margin | H9: =PL!G12/PL!G5
B10: PL | C10: Income statement (history + forecast) | E10: FY2033E EBITDA margin | H10: =PL!O12/PL!O5
B11: BS | C11: Balance sheet (history + forecast) | E11: FY2033E PAT (INR m) | H11: =PL!O22
B12: CS | C12: Cash flow statement (fully articulated) | E12: DCF value per share (INR) | H12: =DCF!C27
B13: Working Capital Schedule | C13: Receivables / inventory / payables & change in NWC | E13: Integrity checks | H13: ='Error Checks'!C22
B14: Working Schedules | C14: PPE, ROU, intangibles, debt, lease, finance cost, tax/losses, D&A
B15: Ratio Analysis | C15: Profitability, liquidity, leverage, efficiency, per-share
B16: DCF | C16: FCFF DCF with CAPM WACC and terminal value
B17: Error Checks | C17: Automated integrity checks (all PASS)
B18: Company & Market Insights | C18: Industry, competition, battery costs, policy, sources
B19: Modelling Notes | C19: Methodology, assumptions rationale, risks, limitations
B21: Colour key:
B22: Blue = hardcoded input
B23: Green = link / reference to another sheet
B24: Black = calculation
B26: Prepared as an equity-research-style model for analytical/educational use. Not investment advice.

Sheet Scenarios
B2: Ather Energy Ltd — Economic / Operating Scenarios
B4: Scenario Switch (1 = Base, 2 = Bull, 3 = Bear) | F4: 1
B5: Currently running: | F5: =CHOOSE($F$4,"BASE","BULL","BEAR")
B7: Vehicle Unit Volume Growth %
C8: 2021 | D8: =C8+1 | E8: =D8+1 | F8: =E8+1 | G8: =F8+1 | H8: =G8+1 | I8: =H8+1 | J8: =I8+1 | K8: =J8+1 | ... O8: =N8+1
B9: Selected (driven by switch) | H9: =CHOOSE($F$4,H11,H12,H13) | I9: =CHOOSE($F$4,I11,I12,I13) | J9: =CHOOSE($F$4,J11,J12,J13) | K9: =CHOOSE($F$4,K11,K12,K13) | L9: =CHOOSE($F$4,L11,L12,L13) | M9: =CHOOSE($F$4,M11,M12,M13) | N9: =CHOOSE($F$4,N11,N12,N13) | O9: =CHOOSE($F$4,O11,O12,O13)
B11: Base | H11: 0.28 | I11: 0.26 | J11: 0.24 | K11: 0.22 | L11: 0.18 | M11: 0.15 | N11: 0.12 | O11: 0.1
B12: Bull | H12: 0.35 | I12: 0.32 | J12: 0.28 | K12: 0.25 | L12: 0.22 | M12: 0.18 | N12: 0.15 | O12: 0.12
B13: Bear | H13: 0.18 | I13: 0.16 | J13: 0.14 | K13: 0.12 | L13: 0.1 | M13: 0.08 | N13: 0.07 | O13: 0.06
B16: Gross Margin %
C17: 2021 | D17: =C17+1 | E17: =D17+1 | F17: =E17+1 | G17: =F17+1 | H17: =G17+1 | I17: =H17+1 | J17: =I17+1 | K17: =J17+1 | ... O17: =N17+1
B18: Selected (driven by switch) | H18: =CHOOSE($F$4,H20,H21,H22) | I18: =CHOOSE($F$4,I20,I21,I22) | J18: =CHOOSE($F$4,J20,J21,J22) | K18: =CHOOSE($F$4,K20,K21,K22) | L18: =CHOOSE($F$4,L20,L21,L22) | M18: =CHOOSE($F$4,M20,M21,M22) | N18: =CHOOSE($F$4,N20,N21,N22) | O18: =CHOOSE($F$4,O20,O21,O22)
B20: Base | H20: 0.18 | I20: 0.2 | J20: 0.22 | K20: 0.24 | L20: 0.255 | M20: 0.265 | N20: 0.275 | O20: 0.28
B21: Bull | H21: 0.2 | I21: 0.225 | J21: 0.245 | K21: 0.265 | L21: 0.28 | M21: 0.29 | N21: 0.3 | O21: 0.305
B22: Bear | H22: 0.155 | I22: 0.165 | J22: 0.18 | K22: 0.19 | L22: 0.2 | M22: 0.21 | N22: 0.22 | O22: 0.225
B26: Note: Volume growth feeds the Revenue Build; Gross Margin feeds the P&L COGS line. Switch one cell (F4) to flex the entire model across Base / Bull / Bear cases.

Sheet Assumptions
B2: Ather Energy Ltd — Assumptions & Key Drivers
B3: All monetary figures in INR millions unless stated. Forecast FY2026E–FY2033E.
B4: Particulars | C4: 2021 | D4: =C4+1 | E4: =D4+1 | F4: =E4+1 | G4: =F4+1 | H4: =G4+1 | I4: =H4+1 | J4: =I4+1 | K4: =J4+1 | ... O4: =N4+1 | Q4: Source | R4: Reason / Simple explanation
B5: A. Macroeconomic & Industry Assumptions
B6: India real GDP growth % | H6: 0.065 | I6: 0.065 | J6: 0.067 | K6: 0.068 | L6: 0.068 | M6: 0.065 | N6: 0.065 | O6: 0.065 | Q6: IMF/RBI projections | R6: Stable ~6.5% growth supports consumer discretionary demand for two-wheelers.
B7: CPI inflation % | H7: 0.045 | I7: 0.045 | J7: 0.045 | K7: 0.045 | L7: 0.045 | M7: 0.045 | N7: 0.045 | O7: 0.045 | Q7: RBI target band (4%±2%) | R7: Moderate inflation; input-cost pressure largely offset by battery cost decline.
B8: RBI repo rate % | H8: 0.06 | I8: 0.0575 | J8: 0.0575 | K8: 0.0575 | L8: 0.06 | M8: 0.06 | N8: 0.06 | O8: 0.06 | Q8: RBI policy outlook | R8: Gradual easing then stable; lowers cost of borrowings & leases.
B9: India 2W industry (m units) | H9: 19.5 | I9: 20.8 | J9: 22 | K9: 23.3 | L9: 24.5 | M9: 25.7 | N9: 26.8 | O9: 27.9 | Q9: SIAM; ~8% CAGR | R9: Overall 2W market grows ~8%; base for E2W penetration math.
B10: E2W penetration of 2W % | H10: 0.075 | I10: 0.095 | J10: 0.12 | K10: 0.15 | L10: 0.18 | M10: 0.22 | N10: 0.26 | O10: 0.3 | Q10: Kearney (30% by 2030); Ather (40% by FY31) | R10: Electric share of 2W rises sharply on cost parity, charging, policy.
B11: E2W industry growth % | H11: 0.25 | I11: 0.28 | J11: 0.3 | K11: 0.32 | L11: 0.28 | M11: 0.26 | N11: 0.22 | O11: 0.18 | Q11: IMARC/Renub/TechSci (26-28% CAGR) | R11: Strong structural growth in electric two-wheelers.
B12: Li-ion battery pack (USD/kWh) | H12: 105 | I12: 99 | J12: 95 | K12: 91 | L12: 88 | M12: 85 | N12: 83 | O12: 81 | Q12: BloombergNEF Dec-2025 ($108 in 2025) | R12: Falling cells/lithium prices cut Ather's largest input cost -> margin tailwind.
B13: Ather E2W market share % | H13: 0.16 | I13: 0.17 | J13: 0.18 | K13: 0.19 | L13: 0.2 | M13: 0.205 | N13: 0.21 | O13: 0.21 | Q13: Vahan; ETAuto (18.7% Mar-26) | R13: Share gains from capacity, products (Rizta), 700+ outlets; tapers as market matures.
B15: B. Revenue Drivers
B16: Vehicle unit volume growth % | H16: =Scenarios!H9 | I16: =Scenarios!I9 | J16: =Scenarios!J9 | K16: =Scenarios!K9 | L16: =Scenarios!L9 | M16: =Scenarios!M9 | N16: =Scenarios!N9 | O16: =Scenarios!O9 | Q16: Scenarios sheet (driver) | R16: Driven by Base/Bull/Bear switch; reflects share gains + market growth, tapering over time.
B17: Realisation / ASP growth % | H17: -0.01 | I17: 0 | J17: 0.01 | K17: 0.01 | L17: 0.015 | M17: 0.02 | N17: 0.02 | O17: 0.02 | Q17: Ather ASP: FY23 155.6k, FY24 143.3k, FY25 ~127.6k | R17: Near-term dip from cheaper Rizta mix, then modest premiumisation/price recovery.
B18: Accessories revenue % of vehicle rev | H18: 0.025 | I18: 0.025 | J18: 0.025 | K18: 0.025 | L18: 0.025 | M18: 0.025 | N18: 0.025 | O18: 0.025 | Q18: AR Note 20; mgmt commentary | R18: Helmets, chargers, spares attach steadily with deliveries.
B19: Software & connectivity % of vehicle rev | H19: 0.015 | I19: 0.018 | J19: 0.02 | K19: 0.022 | L19: 0.025 | M19: 0.027 | N19: 0.03 | O19: 0.03 | Q19: AtherStack/Pro-Pack adoption | R19: High-margin subscriptions rise with connected installed base.
B20: Charging (Ather Grid) % of vehicle rev | H20: 0.005 | I20: 0.005 | J20: 0.005 | K20: 0.005 | L20: 0.005 | M20: 0.005 | N20: 0.005 | O20: 0.005 | Q20: Ather Grid network | R20: Small but growing recurring charging revenue.
B21: Service & after-sales growth % | H21: 0.3 | I21: 0.28 | J21: 0.26 | K21: 0.24 | L21: 0.22 | M21: 0.2 | N21: 0.18 | O21: 0.16 | Q21: AR Note 20 (service rev 1,451m FY25) | R21: Grows with cumulative fleet on road; tapers as base enlarges.
B22: Other operating income (INR m) | H22: 50 | I22: 50 | J22: 50 | K22: 50 | L22: 50 | M22: 50 | N22: 50 | O22: 50 | Q22: Historical run-rate | R22: Scrap, incentives and sundry operating income held broadly flat.
B24: C. Cost & Margin Drivers
B25: Gross margin % | H25: =Scenarios!H18 | I25: =Scenarios!I18 | J25: =Scenarios!J18 | K25: =Scenarios!K18 | L25: =Scenarios!L18 | M25: =Scenarios!M18 | N25: =Scenarios!N18 | O25: =Scenarios!O18 | Q25: Scenarios sheet (driver) | R25: Expands on battery-cost decline, scale, localisation/PLI and mix; Base 18%->28%.
B26: Employee cost % of sales | H26: 0.15 | I26: 0.13 | J26: 0.115 | K26: 0.105 | L26: 0.1 | M26: 0.095 | N26: 0.09 | O26: 0.09 | Q26: FY25 18.3% of sales | R26: Operating leverage: headcount grows slower than revenue.
B27: Other operating expenses % of sales | H27: 0.21 | I27: 0.185 | J27: 0.165 | K27: 0.15 | L27: 0.14 | M27: 0.135 | N27: 0.13 | O27: 0.13 | Q27: FY25 24.2% of sales (S&M, R&D-opex, admin, freight) | R27: Marketing/logistics/admin scale sub-linearly; brand now established.
B28: Warranty provision % of sales (non-cash) | H28: 0.027 | I28: 0.027 | J28: 0.027 | K28: 0.027 | L28: 0.027 | M28: 0.027 | N28: 0.027 | O28: 0.027 | Q28: FY25 warranty 602m | R28: Non-cash provision added back in cash flow.
B29: Share-based payments % of employee cost | H29: 0.18 | I29: 0.18 | J29: 0.18 | K29: 0.18 | L29: 0.18 | M29: 0.18 | N29: 0.18 | O29: 0.18 | Q29: FY25 SBP 831m vs emp 4,124m | R29: Non-cash ESOP charge added back in cash flow.
B31: D. Capital Expenditure, Depreciation & Amortisation
B32: PPE capex % of revenue | H32: 0.09 | I32: 0.07 | J32: 0.05 | K32: 0.045 | L32: 0.04 | M32: 0.038 | N32: 0.035 | O32: 0.035 | Q32: Factory-3 (Maharashtra) IPO use-of-proceeds | R32: Front-loaded capex for capacity tripling, then normalises to maintenance levels.
B33: PPE useful life (years) | H33: 8 | I33: 8 | J33: 8 | K33: 8 | L33: 8 | M33: 8 | N33: 8 | O33: 8 | Q33: Auto plant & equipment | R33: Straight-line depreciation base for PPE.
B34: Intangible additions % of revenue | H34: 0.04 | I34: 0.038 | J34: 0.035 | K34: 0.032 | L34: 0.03 | M34: 0.028 | N34: 0.025 | O34: 0.025 | Q34: Capitalised product/software development | R34: R&D capitalised for new platforms; eases as portfolio matures.
B35: Intangible amortisation % of opening | H35: 0.18 | I35: 0.18 | J35: 0.18 | K35: 0.18 | L35: 0.18 | M35: 0.18 | N35: 0.18 | O35: 0.18 | Q35: ~5-6 yr life | R35: Tech/software amortised over useful life.
B36: ROU (lease) additions % of revenue | H36: 0.03 | I36: 0.028 | J36: 0.025 | K36: 0.022 | L36: 0.02 | M36: 0.018 | N36: 0.016 | O36: 0.015 | Q36: Retail (700+ outlets) & warehouse leases | R36: New experience-centre/warehouse leases scale with network, then taper.
B37: ROU amortisation % | H37: 0.22 | I37: 0.22 | J37: 0.22 | K37: 0.22 | L37: 0.22 | M37: 0.22 | N37: 0.22 | O37: 0.22 | Q37: Avg lease ~4-5 yrs | R37: Straight-line amortisation of right-of-use assets.
B39: E. Financing & Tax
B40: Interest rate on borrowings % | H40: 0.1 | I40: 0.1 | J40: 0.1 | K40: 0.1 | L40: 0.1 | M40: 0.1 | N40: 0.1 | O40: 0.1 | Q40: FY25 finance cost / debt | R40: Blended rate on working-capital + term debt.
B41: Net borrowing draw/(repay) (INR m) | H41: 1500 | I41: 500 | J41: 1500 | K41: 2000 | L41: 1500 | M41: 500 | N41: -1000 | O41: -1500 | Q41: Mgmt: working-capital + term debt for capacity build | R41: Modest debt draws fund the capex/loss trough (FY26-FY30), repaid once free cash flow turns positive (FY32-FY33).
B42: Lease interest rate % | H42: 0.09 | I42: 0.09 | J42: 0.09 | K42: 0.09 | L42: 0.09 | M42: 0.09 | N42: 0.09 | O42: 0.09 | Q42: Ind AS 116 incremental borrowing rate | R42: Interest unwound on lease liabilities.
B43: Lease principal repayment growth % | H43: 0.1 | I43: 0.1 | J43: 0.1 | K43: 0.1 | L43: 0.1 | M43: 0.1 | N43: 0.1 | O43: 0.1 | Q43: Historical lease repayment trend | R43: Lease principal outflow grows with expanding lease base.
B44: Interest income rate on cash & inv % | H44: 0.06 | I44: 0.06 | J44: 0.06 | K44: 0.06 | L44: 0.06 | M44: 0.06 | N44: 0.06 | O44: 0.06 | Q44: Yield on deposits/MFs | R44: Earned on opening cash, term deposits and liquid investments.
B45: Equity issuance / IPO (INR m) | H45: 26000 | I45: 0 | J45: 0 | K45: 0 | L45: 0 | M45: 0 | N45: 0 | O45: 0 | Q45: IPO May-2025 fresh issue ~INR 2,626 cr | R45: One-off FY26 primary equity raise (Factory-3, R&D, debt, marketing).
...

Sheet Revenue Build
B2: Ather Energy Ltd — Revenue Build (driver-based)
B3: Units in numbers; ASP in INR/vehicle; all revenue in INR millions.
B4: Particulars | C4: 2021 | D4: =C4+1 | E4: =D4+1 | F4: =E4+1 | G4: =F4+1 | H4: =G4+1 | I4: =H4+1 | J4: =I4+1 | K4: =J4+1 | ... O4: =N4+1
B6: Vehicle volumes (units) | C6: 7100 | D6: 26000 | E6: 106000 | F6: 113900 | G6: 165000 | H6: =G6*(1+Assumptions!H16) | I6: =H6*(1+Assumptions!I16) | J6: =I6*(1+Assumptions!J16) | K6: =J6*(1+Assumptions!K16) | L6: =K6*(1+Assumptions!L16) | M6: =L6*(1+Assumptions!M16) | N6: =M6*(1+Assumptions!N16) | O6: =N6*(1+Assumptions!O16)
B7: Average Selling Price (INR / vehicle) | C7: 98592 | D7: 138462 | E7: 154717 | F7: 143292 | G7: 127606 | H7: =G7*(1+Assumptions!H17) | I7: =H7*(1+Assumptions!I17) | J7: =I7*(1+Assumptions!J17) | K7: =J7*(1+Assumptions!K17) | L7: =K7*(1+Assumptions!L17) | M7: =L7*(1+Assumptions!M17) | N7: =M7*(1+Assumptions!N17) | O7: =N7*(1+Assumptions!O17)
B8: Vehicle revenue | C8: =C6*C7/1000000 | D8: =D6*D7/1000000 | E8: =E6*E7/1000000 | F8: =F6*F7/1000000 | G8: =G6*G7/1000000 | H8: =H6*H7/1000000 | I8: =I6*I7/1000000 | J8: =J6*J7/1000000 | ... O8: =O6*O7/1000000
B9: Accessories & spares revenue | C9: 18 | D9: 90 | E9: 250 | F9: 0 | G9: 0 | H9: =H8*Assumptions!H18 | I9: =I8*Assumptions!I18 | J9: =J8*Assumptions!J18 | K9: =K8*Assumptions!K18 | L9: =L8*Assumptions!L18 | M9: =M8*Assumptions!M18 | N9: =N8*Assumptions!N18 | O9: =O8*Assumptions!O18
B10: Software & connectivity revenue | C10: 5 | D10: 20 | E10: 80 | F10: 0 | G10: 0 | H10: =H8*Assumptions!H19 | I10: =I8*Assumptions!I19 | J10: =J8*Assumptions!J19 | K10: =K8*Assumptions!K19 | L10: =L8*Assumptions!L19 | M10: =M8*Assumptions!M19 | N10: =N8*Assumptions!N19 | O10: =O8*Assumptions!O19
B11: Charging (Ather Grid) revenue | C11: 0 | D11: 5 | E11: 20 | F11: 0 | G11: 0 | H11: =H8*Assumptions!H20 | I11: =I8*Assumptions!I20 | J11: =J8*Assumptions!J20 | K11: =K8*Assumptions!K20 | L11: =L8*Assumptions!L20 | M11: =M8*Assumptions!M20 | N11: =N8*Assumptions!N20 | O11: =O8*Assumptions!O20
B12: Service & after-sales revenue | C12: 55 | D12: 320 | E12: 1000 | F12: 1190 | G12: 1451 | H12: =G12*(1+Assumptions!H21) | I12: =H12*(1+Assumptions!I21) | J12: =I12*(1+Assumptions!J21) | K12: =J12*(1+Assumptions!K21) | L12: =K12*(1+Assumptions!L21) | M12: =L12*(1+Assumptions!M21) | N12: =M12*(1+Assumptions!N21) | O12: =N12*(1+Assumptions!O21)
B13: Other operating income | C13: 20 | D13: 50 | E13: 86 | F13: 27 | G13: 44 | H13: =Assumptions!H22 | I13: =Assumptions!I22 | J13: =Assumptions!J22 | K13: =Assumptions!K22 | L13: =Assumptions!L22 | M13: =Assumptions!M22 | N13: =Assumptions!N22 | O13: =Assumptions!O22
B14: Total revenue from operations | C14: =SUM(C8:C13) | D14: =SUM(D8:D13) | E14: =SUM(E8:E13) | F14: =SUM(F8:F13) | G14: =SUM(G8:G13) | H14: =SUM(H8:H13) | I14: =SUM(I8:I13) | J14: =SUM(J8:J13) | ... O14: =SUM(O8:O13)
B16: Memo:
B17: Total revenue growth % | D17: =D14/C14-1 | E17: =E14/D14-1 | F17: =F14/E14-1 | G17: =G14/F14-1 | H17: =H14/G14-1 | I17: =I14/H14-1 | J17: =J14/I14-1 | K17: =K14/J14-1 | ... O17: =O14/N14-1
B18: Non-vehicle revenue % of total | C18: =(C14-C8)/C14 | D18: =(D14-D8)/D14 | E18: =(E14-E8)/E14 | F18: =(F14-F8)/F14 | G18: =(G14-G8)/G14 | H18: =(H14-H8)/H14 | I18: =(I14-I8)/I14 | J18: =(J14-J8)/J14 | ... O18: =(O14-O8)/O14

Sheet PL
B2: Ather Energy Ltd — Income Statement (INR millions) | R2: =CONCATENATE("Scenario: ",Scenarios!F5)
B4: Particulars | C4: 2021 | D4: =C4+1 | E4: =D4+1 | F4: =E4+1 | G4: =F4+1 | H4: =G4+1 | I4: =H4+1 | J4: =I4+1 | K4: =J4+1 | ... O4: =N4+1
B5: Revenue from operations | C5: 798 | D5: 4085 | E5: 17836 | F5: 17538 | G5: 22550 | H5: ='Revenue Build'!H14 | I5: ='Revenue Build'!I14 | J5: ='Revenue Build'!J14 | K5: ='Revenue Build'!K14 | L5: ='Revenue Build'!L14 | M5: ='Revenue Build'!M14 | N5: ='Revenue Build'!N14 | O5: ='Revenue Build'!O14
B6: Total cost of goods sold | C6: -917 | D6: -3916 | E6: -18200 | F6: -16318 | G6: -18768 | H6: =-H5*(1-Assumptions!H25) | I6: =-I5*(1-Assumptions!I25) | J6: =-J5*(1-Assumptions!J25) | K6: =-K5*(1-Assumptions!K25) | L6: =-L5*(1-Assumptions!L25) | M6: =-M5*(1-Assumptions!M25) | N6: =-N5*(1-Assumptions!N25) | O6: =-O5*(1-Assumptions!O25)
B7: Gross Profit | C7: =C5+C6 | D7: =D5+D6 | E7: =E5+E6 | F7: =F5+F6 | G7: =G5+G6 | H7: =H5+H6 | I7: =I5+I6 | J7: =J5+J6 | ... O7: =O5+O6
B8: Operating expenses
B9: Employee benefits expense | C9: -657 | D9: -1148 | E9: -2600 | F9: -3692 | G9: -4124 | H9: =-H5*Assumptions!H26 | I9: =-I5*Assumptions!I26 | J9: =-J5*Assumptions!J26 | K9: =-K5*Assumptions!K26 | L9: =-L5*Assumptions!L26 | M9: =-M5*Assumptions!M26 | N9: =-N5*Assumptions!N26 | O9: =-O5*Assumptions!O26
B10: Other operating expenses | C10: -1015 | D10: -1634 | E10: -4078 | F10: -4375 | G10: -5467 | H10: =-H5*Assumptions!H27 | I10: =-I5*Assumptions!I27 | J10: =-J5*Assumptions!J27 | K10: =-K5*Assumptions!K27 | L10: =-L5*Assumptions!L27 | M10: =-M5*Assumptions!M27 | N10: =-N5*Assumptions!N27 | O10: =-O5*Assumptions!O27
B11: Total operating expenses | C11: =SUM(C9:C10) | D11: =SUM(D9:D10) | E11: =SUM(E9:E10) | F11: =SUM(F9:F10) | G11: =SUM(G9:G10) | H11: =SUM(H9:H10) | I11: =SUM(I9:I10) | J11: =SUM(J9:J10) | ... O11: =SUM(O9:O10)
B12: EBITDA | C12: =C7+C11 | D12: =D7+D11 | E12: =E7+E11 | F12: =F7+F11 | G12: =G7+G11 | H12: =H7+H11 | I12: =I7+I11 | J12: =J7+J11 | ... O12: =O7+O11
B13: Depreciation & amortisation | C13: -351 | D13: -484 | E13: -1128 | F13: -1467 | G13: -1710 | H13: ='Working Schedules'!H33 | I13: ='Working Schedules'!I33 | J13: ='Working Schedules'!J33 | K13: ='Working Schedules'!K33 | L13: ='Working Schedules'!L33 | M13: ='Working Schedules'!M33 | N13: ='Working Schedules'!N33 | O13: ='Working Schedules'!O33
B14: EBIT | C14: =C12+C13 | D14: =D12+D13 | E14: =E12+E13 | F14: =F12+F13 | G14: =G12+G13 | H14: =H12+H13 | I14: =I12+I13 | J14: =J12+J13 | ... O14: =O12+O13
B15: Other income | C15: 85 | D15: 54 | E15: 225 | F15: 353 | G15: 502 | H15: 0 | I15: 0 | J15: 0 | K15: 0 | L15: 0 | M15: 0 | N15: 0 | O15: 0
B16: Exceptional items | C16: 0 | D16: 0 | E16: 0 | F16: -1746 | G16: 0 | H16: 0 | I16: 0 | J16: 0 | K16: 0 | L16: 0 | M16: 0 | N16: 0 | O16: 0
B17: Finance costs | C17: -276 | D17: -398 | E17: -700 | F17: -890 | G17: -1106 | H17: =-'Working Schedules'!H53 | I17: =-'Working Schedules'!I53 | J17: =-'Working Schedules'!J53 | K17: =-'Working Schedules'!K53 | L17: =-'Working Schedules'!L53 | M17: =-'Working Schedules'!M53 | N17: =-'Working Schedules'!N53 | O17: =-'Working Schedules'!O53
B18: Interest income | C18: 0 | D18: 0 | E18: 0 | F18: 0 | G18: 0 | H18: =BS!G43*Assumptions!H44 | I18: =BS!H43*Assumptions!I44 | J18: =BS!I43*Assumptions!J44 | K18: =BS!J43*Assumptions!K44 | L18: =BS!K43*Assumptions!L44 | M18: =BS!L43*Assumptions!M44 | N18: =BS!M43*Assumptions!N44 | O18: =BS!N43*Assumptions!O44
B19: Profit / (Loss) before tax | C19: =SUM(C14:C18) | D19: =SUM(D14:D18) | E19: =SUM(E14:E18) | F19: =SUM(F14:F18) | G19: =SUM(G14:G18) | H19: =SUM(H14:H18) | I19: =SUM(I14:I18) | J19: =SUM(J14:J18) | ... O19: =SUM(O14:O18)
B20: Tax expense | C20: 0 | D20: 0 | E20: 0 | F20: 0 | G20: 0 | H20: =-'Working Schedules'!H62 | I20: =-'Working Schedules'!I62 | J20: =-'Working Schedules'!J62 | K20: =-'Working Schedules'!K62 | L20: =-'Working Schedules'!L62 | M20: =-'Working Schedules'!M62 | N20: =-'Working Schedules'!N62 | O20: =-'Working Schedules'!O62
B21: Adjustments / share of associates | C21: 0 | D21: 0 | E21: 0 | F21: 0 | G21: 0 | H21: 0 | I21: 0 | J21: 0 | K21: 0 | L21: 0 | M21: 0 | N21: 0 | O21: 0
B22: Profit / (Loss) after tax (PAT) | C22: =C19+C20+C21 | D22: =D19+D20+D21 | E22: =E19+E20+E21 | F22: =F19+F20+F21 | G22: =G19+G20+G21 | H22: =H19+H20+H21 | I22: =I19+I20+I21 | J22: =J19+J20+J21 | ... O22: =O19+O20+O21

Sheet BS
B2: Ather Energy Ltd — Balance Sheet (INR millions)
B4: Particulars | C4: 2021 | D4: =C4+1 | E4: =D4+1 | F4: =E4+1 | G4: =F4+1 | H4: =G4+1 | I4: =H4+1 | J4: =I4+1 | K4: =J4+1 | ... O4: =N4+1
B6: EQUITY & LIABILITIES
B7: Shareholders' funds
B8: Equity share capital & instruments | C8: 4 | D8: 7 | E8: 6 | F8: 8 | G8: 291 | H8: =G8+81 | I8: =H8 | J8: =I8 | K8: =J8 | L8: =K8 | M8: =L8 | N8: =M8 | O8: =N8
B9: Other equity (reserves & surplus) | C9: 3758 | D9: 2242 | E9: 6131 | F9: 5451 | G9: 4639 | H9: =G9+PL!H22+Assumptions!H45-(H8-G8)+(-PL!H9)*Assumptions!H29 | I9: =H9+PL!I22+Assumptions!I45-(I8-H8)+(-PL!I9)*Assumptions!I29 | J9: =I9+PL!J22+Assumptions!J45-(J8-I8)+(-PL!J9)*Assumptions!J29 | K9: =J9+PL!K22+Assumptions!K45-(K8-J8)+(-PL!K9)*Assumptions!K29 | L9: =K9+PL!L22+Assumptions!L45-(L8-K8)+(-PL!L9)*Assumptions!L29 | M9: =L9+PL!M22+Assumptions!M45-(M8-L8)+(-PL!M9)*Assumptions!M29 | N9: =M9+PL!N22+Assumptions!N45-(N8-M8)+(-PL!N9)*Assumptions!N29 | O9: =N9+PL!O22+Assumptions!O45-(O8-N8)+(-PL!O9)*Assumptions!O29
B10: Total equity | C10: =C8+C9 | D10: =D8+D9 | E10: =E8+E9 | F10: =F8+F9 | G10: =G8+G9 | H10: =H8+H9 | I10: =I8+I9 | J10: =J8+J9 | ... O10: =O8+O9
B12: Non-current liabilities
B13: Long-term borrowings | C13: 1108 | D13: 1088 | E13: 1200 | F13: 309 | G13: 1169 | H13: ='Working Schedules'!H39*($G$13/($G$13+$G$21)) | I13: ='Working Schedules'!I39*($G$13/($G$13+$G$21)) | J13: ='Working Schedules'!J39*($G$13/($G$13+$G$21)) | K13: ='Working Schedules'!K39*($G$13/($G$13+$G$21)) | L13: ='Working Schedules'!L39*($G$13/($G$13+$G$21)) | M13: ='Working Schedules'!M39*($G$13/($G$13+$G$21)) | N13: ='Working Schedules'!N39*($G$13/($G$13+$G$21)) | O13: ='Working Schedules'!O39*($G$13/($G$13+$G$21))
B14: Lease liabilities (non-current) | C14: 375 | D14: 597 | E14: 1600 | F14: 1419 | G14: 1431 | H14: ='Working Schedules'!H47*($G$14/($G$14+$G$22)) | I14: ='Working Schedules'!I47*($G$14/($G$14+$G$22)) | J14: ='Working Schedules'!J47*($G$14/($G$14+$G$22)) | K14: ='Working Schedules'!K47*($G$14/($G$14+$G$22)) | L14: ='Working Schedules'!L47*($G$14/($G$14+$G$22)) | M14: ='Working Schedules'!M47*($G$14/($G$14+$G$22)) | N14: ='Working Schedules'!N47*($G$14/($G$14+$G$22)) | O14: ='Working Schedules'!O47*($G$14/($G$14+$G$22))
B15: Long-term provisions | C15: 124 | D15: 290 | E15: 480 | F15: 702 | G15: 792 | H15: =$G$15/PL!$G$5*PL!H5 | I15: =$G$15/PL!$G$5*PL!I5 | J15: =$G$15/PL!$G$5*PL!J5 | K15: =$G$15/PL!$G$5*PL!K5 | L15: =$G$15/PL!$G$5*PL!L5 | M15: =$G$15/PL!$G$5*PL!M5 | N15: =$G$15/PL!$G$5*PL!N5 | O15: =$G$15/PL!$G$5*PL!O5
B16: Other non-current liabilities | C16: 6 | D16: 19 | E16: 200 | F16: 482 | G16: 952 | H16: =$G$16/PL!$G$5*PL!H5 | I16: =$G$16/PL!$G$5*PL!I5 | J16: =$G$16/PL!$G$5*PL!J5 | K16: =$G$16/PL!$G$5*PL!K5 | L16: =$G$16/PL!$G$5*PL!L5 | M16: =$G$16/PL!$G$5*PL!M5 | N16: =$G$16/PL!$G$5*PL!N5 | O16: =$G$16/PL!$G$5*PL!O5
B17: Total non-current liabilities | C17: =SUM(C13:C16) | D17: =SUM(D13:D16) | E17: =SUM(E13:E16) | F17: =SUM(F13:F16) | G17: =SUM(G13:G16) | H17: =SUM(H13:H16) | I17: =SUM(I13:I16) | J17: =SUM(J13:J16) | ... O17: =SUM(O13:O16)
B19: Current liabilities
B20: Trade payables | C20: 676 | D20: 1216 | E20: 2400 | F20: 4027 | G20: 5609 | H20: ='Working Capital Schedule'!H15 | I20: ='Working Capital Schedule'!I15 | J20: ='Working Capital Schedule'!J15 | K20: ='Working Capital Schedule'!K15 | L20: ='Working Capital Schedule'!L15 | M20: ='Working Capital Schedule'!M15 | N20: ='Working Capital Schedule'!N15 | O20: ='Working Capital Schedule'!O15
B21: Short-term borrowings | C21: 609 | D21: 1897 | E21: 3652 | F21: 2840 | G21: 3330 | H21: ='Working Schedules'!H39*($G$21/($G$13+$G$21)) | I21: ='Working Schedules'!I39*($G$21/($G$13+$G$21)) | J21: ='Working Schedules'!J39*($G$21/($G$13+$G$21)) | K21: ='Working Schedules'!K39*($G$21/($G$13+$G$21)) | L21: ='Working Schedules'!L39*($G$21/($G$13+$G$21)) | M21: ='Working Schedules'!M39*($G$21/($G$13+$G$21)) | N21: ='Working Schedules'!N39*($G$21/($G$13+$G$21)) | O21: ='Working Schedules'!O39*($G$21/($G$13+$G$21))
B22: Lease liabilities (current) | C22: 97 | D22: 68 | E22: 264 | F22: 209 | G22: 263 | H22: ='Working Schedules'!H47*($G$22/($G$14+$G$22)) | I22: ='Working Schedules'!I47*($G$22/($G$14+$G$22)) | J22: ='Working Schedules'!J47*($G$22/($G$14+$G$22)) | K22: ='Working Schedules'!K47*($G$22/($G$14+$G$22)) | L22: ='Working Schedules'!L47*($G$22/($G$14+$G$22)) | M22: ='Working Schedules'!M47*($G$22/($G$14+$G$22)) | N22: ='Working Schedules'!N47*($G$22/($G$14+$G$22)) | O22: ='Working Schedules'!O47*($G$22/($G$14+$G$22))
B23: Short-term provisions | C23: 44 | D23: 105 | E23: 400 | F23: 807 | G23: 1189 | H23: =Assumptions!H55*PL!H5 | I23: =Assumptions!I55*PL!I5 | J23: =Assumptions!J55*PL!J5 | K23: =Assumptions!K55*PL!K5 | L23: =Assumptions!L55*PL!L5 | M23: =Assumptions!M55*PL!M5 | N23: =Assumptions!N55*PL!N5 | O23: =Assumptions!O55*PL!O5
B24: Other current liabilities | C24: 612 | D24: 657 | E24: 1400 | F24: 2881 | G24: 1341 | H24: =Assumptions!H54*PL!H5 | I24: =Assumptions!I54*PL!I5 | J24: =Assumptions!J54*PL!J5 | K24: =Assumptions!K54*PL!K5 | L24: =Assumptions!L54*PL!L5 | M24: =Assumptions!M54*PL!M5 | N24: =Assumptions!N54*PL!N5 | O24: =Assumptions!O54*PL!O5
B25: Total current liabilities | C25: =SUM(C20:C24) | D25: =SUM(D20:D24) | E25: =SUM(E20:E24) | F25: =SUM(F20:F24) | G25: =SUM(G20:G24) | H25: =SUM(H20:H24) | I25: =SUM(I20:I24) | J25: =SUM(J20:J24) | ... O25: =SUM(O20:O24)
B27: TOTAL EQUITY & LIABILITIES | C27: =C10+C17+C25 | D27: =D10+D17+D25 | E27: =E10+E17+E25 | F27: =F10+F17+F25 | G27: =G10+G17+G25 | H27: =H10+H17+H25 | I27: =I10+I17+I25 | J27: =J10+J17+J25 | ... O27: =O10+O17+O25
B29: ASSETS
B30: Non-current assets
B31: Property, plant & equipment | C31: 800 | D31: 931 | E31: 1400 | F31: 1871 | G31: 2674 | H31: ='Working Schedules'!H9 | I31: ='Working Schedules'!I9 | J31: ='Working Schedules'!J9 | K31: ='Working Schedules'!K9 | L31: ='Working Schedules'!L9 | M31: ='Working Schedules'!M9 | N31: ='Working Schedules'!N9 | O31: ='Working Schedules'!O9
B32: Capital work-in-progress | C32: 1 | D32: 4 | E32: 2 | F32: 0 | G32: 57 | H32: ='Working Schedules'!H27 | I32: ='Working Schedules'!I27 | J32: ='Working Schedules'!J27 | K32: ='Working Schedules'!K27 | L32: ='Working Schedules'!L27 | M32: ='Working Schedules'!M27 | N32: ='Working Schedules'!N27 | O32: ='Working Schedules'!O27
B33: Right-of-use assets | C33: 444 | D33: 646 | E33: 1700 | F33: 1489 | G33: 2443 | H33: ='Working Schedules'!H16 | I33: ='Working Schedules'!I16 | J33: ='Working Schedules'!J16 | K33: ='Working Schedules'!K16 | L33: ='Working Schedules'!L16 | M33: ='Working Schedules'!M16 | N33: ='Working Schedules'!N16 | O33: ='Working Schedules'!O16
B34: Intangible assets (incl. under dev.) | C34: 2294 | D34: 2692 | E34: 2300 | F34: 1935 | G34: 2206 | H34: ='Working Schedules'!H23 | I34: ='Working Schedules'!I23 | J34: ='Working Schedules'!J23 | K34: ='Working Schedules'!K23 | L34: ='Working Schedules'!L23 | M34: ='Working Schedules'!M23 | N34: ='Working Schedules'!N23 | O34: ='Working Schedules'!O23
B35: Total fixed assets | C35: =SUM(C31:C34) | D35: =SUM(D31:D34) | E35: =SUM(E31:E34) | F35: =SUM(F31:F34) | G35: =SUM(G31:G34) | H35: =SUM(H31:H34) | I35: =SUM(I31:I34) | J35: =SUM(J31:J34) | ... O35: =SUM(O31:O34)
B36: Other non-current assets | C36: 1289 | D36: 987 | E36: 1200 | F36: 1546 | G36: 2058 | H36: =$G$36/PL!$G$5*PL!H5 | I36: =$G$36/PL!$G$5*PL!I5 | J36: =$G$36/PL!$G$5*PL!J5 | K36: =$G$36/PL!$G$5*PL!K5 | L36: =$G$36/PL!$G$5*PL!L5 | M36: =$G$36/PL!$G$5*PL!M5 | N36: =$G$36/PL!$G$5*PL!N5 | O36: =$G$36/PL!$G$5*PL!O5
B37: Total non-current assets | C37: =C35+C36 | D37: =D35+D36 | E37: =E35+E36 | F37: =F35+F36 | G37: =G35+G36 | H37: =H35+H36 | I37: =I35+I36 | J37: =J35+J36 | ... O37: =O35+O36
B39: Current assets
B40: Trade receivables | C40: 0 | D40: 10 | E40: 12 | F40: 16 | G40: 118 | H40: ='Working Capital Schedule'!H9 | I40: ='Working Capital Schedule'!I9 | J40: ='Working Capital Schedule'!J9 | K40: ='Working Capital Schedule'!K9 | L40: ='Working Capital Schedule'!L9 | M40: ='Working Capital Schedule'!M9 | N40: ='Working Capital Schedule'!N9 | O40: ='Working Capital Schedule'!O9
B41: Inventories | C41: 567 | D41: 607 | E41: 2574 | F41: 1167 | G41: 2446 | H41: ='Working Capital Schedule'!H12 | I41: ='Working Capital Schedule'!I12 | J41: ='Working Capital Schedule'!J12 | K41: ='Working Capital Schedule'!K12 | L41: ='Working Capital Schedule'!L12 | M41: ='Working Capital Schedule'!M12 | N41: ='Working Capital Schedule'!N12 | O41: ='Working Capital Schedule'!O12
B42: Other current assets | C42: 541 | D42: 1049 | E42: 4819 | F42: 3711 | G42: 4890 | H42: =Assumptions!H53*PL!H5 | I42: =Assumptions!I53*PL!I5 | J42: =Assumptions!J53*PL!J5 | K42: =Assumptions!K53*PL!K5 | L42: =Assumptions!L53*PL!L5 | M42: =Assumptions!M53*PL!M5 | N42: =Assumptions!N53*PL!N5 | O42: =Assumptions!O53*PL!O5
B43: Cash, bank & current investments | C43: 1477 | D43: 1260 | E43: 3726 | F43: 7400 | G43: 4114 | H43: =CS!H30 | I43: =CS!I30 | J43: =CS!J30 | K43: =CS!K30 | L43: =CS!L30 | M43: =CS!M30 | N43: =CS!N30 | O43: =CS!O30
B44: Total current assets | C44: =SUM(C40:C43) | D44: =SUM(D40:D43) | E44: =SUM(E40:E43) | F44: =SUM(F40:F43) | G44: =SUM(G40:G43) | H44: =SUM(H40:H43) | I44: =SUM(I40:I43) | J44: =SUM(J40:J43) | ... O44: =SUM(O40:O43)
B46: TOTAL ASSETS | C46: =C37+C44 | D46: =D37+D44 | E46: =E37+E44 | F46: =F37+F44 | G46: =G37+G44 | H46: =H37+H44 | I46: =I37+I44 | J46: =J37+J44 | ... O46: =O37+O44
B48: Balance check (Assets − Equity & Liab.) | C48: =C46-C27 | D48: =D46-D27 | E48: =E46-E27 | F48: =F46-F27 | G48: =G46-G27 | H48: =H46-H27 | I48: =I46-I27 | J48: =J46-J27 | ... O48: =O46-O27

Sheet CS
B2: Ather Energy Ltd — Cash Flow Statement (INR millions)
B4: Particulars | C4: 2021 | D4: =C4+1 | E4: =D4+1 | F4: =E4+1 | G4: =F4+1 | H4: =G4+1 | I4: =H4+1 | J4: =I4+1 | K4: =J4+1 | ... O4: =N4+1
B5: A. Operating activities
B6: Profit / (Loss) after tax | C6: -2333 | D6: -3441 | E6: -8645 | F6: -10597 | G6: -8123 | H6: =PL!H22 | I6: =PL!I22 | J6: =PL!J22 | K6: =PL!K22 | L6: =PL!L22 | M6: =PL!M22 | N6: =PL!N22 | O6: =PL!O22
B7: Add: Depreciation & amortisation | C7: 351 | D7: 484 | E7: 1128 | F7: 1467 | G7: 1710 | H7: =-PL!H13 | I7: =-PL!I13 | J7: =-PL!J13 | K7: =-PL!K13 | L7: =-PL!L13 | M7: =-PL!M13 | N7: =-PL!N13 | O7: =-PL!O13
B8: Add: Finance costs | C8: 276 | D8: 398 | E8: 700 | F8: 890 | G8: 1106 | H8: =-PL!H17 | I8: =-PL!I17 | J8: =-PL!J17 | K8: =-PL!K17 | L8: =-PL!L17 | M8: =-PL!M17 | N8: =-PL!N17 | O8: =-PL!O17
B9: Less: Interest income | C9: 0 | D9: 0 | E9: 0 | F9: 0 | G9: 0 | H9: =-PL!H18 | I9: =-PL!I18 | J9: =-PL!J18 | K9: =-PL!K18 | L9: =-PL!L18 | M9: =-PL!M18 | N9: =-PL!N18 | O9: =-PL!O18
B10: Add: Non-cash items (ESOP/share-based pay) | C10: 227 | D10: 359 | E10: 520 | F10: 500 | G10: 640 | H10: =(-PL!H9)*Assumptions!H29 | I10: =(-PL!I9)*Assumptions!I29 | J10: =(-PL!J9)*Assumptions!J29 | K10: =(-PL!K9)*Assumptions!K29 | L10: =(-PL!L9)*Assumptions!L29 | M10: =(-PL!M9)*Assumptions!M29 | N10: =(-PL!N9)*Assumptions!N29 | O10: =(-PL!O9)*Assumptions!O29
B11: Change in net working capital | C11: 138 | D11: -260 | E11: -1500 | F11: 1407 | G11: -1278 | H11: =-'Working Capital Schedule'!H21 | I11: =-'Working Capital Schedule'!I21 | J11: =-'Working Capital Schedule'!J21 | K11: =-'Working Capital Schedule'!K21 | L11: =-'Working Capital Schedule'!L21 | M11: =-'Working Capital Schedule'!M21 | N11: =-'Working Capital Schedule'!N21 | O11: =-'Working Capital Schedule'!O21
B12: Change in other non-current items | C12: 0 | D12: 0 | E12: 0 | F12: 0 | G12: 0 | H12: =(BS!H15+BS!H16-BS!G15-BS!G16)-(BS!H36-BS!G36) | I12: =(BS!I15+BS!I16-BS!H15-BS!H16)-(BS!I36-BS!H36) | J12: =(BS!J15+BS!J16-BS!I15-BS!I16)-(BS!J36-BS!I36) | K12: =(BS!K15+BS!K16-BS!J15-BS!J16)-(BS!K36-BS!J36) | L12: =(BS!L15+BS!L16-BS!K15-BS!K16)-(BS!L36-BS!K36) | M12: =(BS!M15+BS!M16-BS!L15-BS!L16)-(BS!M36-BS!L36) | N12: =(BS!N15+BS!N16-BS!M15-BS!M16)-(BS!N36-BS!M36) | O12: =(BS!O15+BS!O16-BS!N15-BS!N16)-(BS!O36-BS!N36)
B13: Cash flow from operating activities | C13: =SUM(C6:C12) | D13: =SUM(D6:D12) | E13: =SUM(E6:E12) | F13: =SUM(F6:F12) | G13: =SUM(G6:G12) | H13: =SUM(H6:H12) | I13: =SUM(I6:I12) | J13: =SUM(J6:J12) | ... O13: =SUM(O6:O12)
B14: B. Investing activities
B15: Interest income received | C15: 33 | D15: 18 | E15: 40 | F15: 196 | G15: 190 | H15: =PL!H18 | I15: =PL!I18 | J15: =PL!J18 | K15: =PL!K18 | L15: =PL!L18 | M15: =PL!M18 | N15: =PL!N18 | O15: =PL!O18
B16: Capex — PPE & CWIP | C16: -700 | D16: -560 | E16: -900 | F16: -900 | G16: -2600 | H16: =-'Working Schedules'!H7 | I16: =-'Working Schedules'!I7 | J16: =-'Working Schedules'!J7 | K16: =-'Working Schedules'!K7 | L16: =-'Working Schedules'!L7 | M16: =-'Working Schedules'!M7 | N16: =-'Working Schedules'!N7 | O16: =-'Working Schedules'!O7
B17: Capex — intangibles / development | C17: -170 | D17: -152 | E17: -300 | F17: -259 | G17: -790 | H17: =-'Working Schedules'!H21 | I17: =-'Working Schedules'!I21 | J17: =-'Working Schedules'!J21 | K17: =-'Working Schedules'!K21 | L17: =-'Working Schedules'!L21 | M17: =-'Working Schedules'!M21 | N17: =-'Working Schedules'!N21 | O17: =-'Working Schedules'!O21
B18: Other investing (deposits/investments, net) | C18: -590 | D18: 638 | E18: -1900 | F18: -1318 | G18: -582 | H18: 0 | I18: 0 | J18: 0 | K18: 0 | L18: 0 | M18: 0 | N18: 0 | O18: 0
B19: Cash flow from investing activities | C19: =SUM(C15:C18) | D19: =SUM(D15:D18) | E19: =SUM(E15:E18) | F19: =SUM(F15:F18) | G19: =SUM(G15:G18) | H19: =SUM(H15:H18) | I19: =SUM(I15:I18) | J19: =SUM(J15:J18) | ... O19: =SUM(O15:O18)
B20: C. Financing activities
B21: Proceeds / (repayment) of borrowings, net | C21: -98 | D21: 1268 | E21: 452 | F21: -541 | G21: 3247 | H21: ='Working Schedules'!H38 | I21: ='Working Schedules'!I38 | J21: ='Working Schedules'!J38 | K21: ='Working Schedules'!K38 | L21: ='Working Schedules'!L38 | M21: ='Working Schedules'!M38 | N21: ='Working Schedules'!N38 | O21: ='Working Schedules'!O38
B22: Lease principal repayment | C22: -100 | D22: -152 | E22: -180 | F22: -168 | G22: -211 | H22: ='Working Schedules'!H46 | I22: ='Working Schedules'!I46 | J22: ='Working Schedules'!J46 | K22: ='Working Schedules'!K46 | L22: ='Working Schedules'!L46 | M22: ='Working Schedules'!M46 | N22: ='Working Schedules'!N46 | O22: ='Working Schedules'!O46
B23: Finance costs paid | C23: -276 | D23: -341 | E23: -700 | F23: -770 | G23: -973 | H23: =PL!H17 | I23: =PL!I17 | J23: =PL!J17 | K23: =PL!K17 | L23: =PL!L17 | M23: =PL!M17 | N23: =PL!N17 | O23: =PL!O17
B24: Equity issuance (IPO / fund raises) | C24: 3439 | D24: 1500 | E24: 9000 | F24: 9011 | G24: 866 | H24: =Assumptions!H45 | I24: =Assumptions!I45 | J24: =Assumptions!J45 | K24: =Assumptions!K45 | L24: =Assumptions!L45 | M24: =Assumptions!M45 | N24: =Assumptions!N45 | O24: =Assumptions!O45
B25: Dividends paid | C25: 0 | D25: 0 | E25: 0 | F25: 0 | G25: 0 | H25: =-Assumptions!H46*MAX(PL!H22,0) | I25: =-Assumptions!I46*MAX(PL!I22,0) | J25: =-Assumptions!J46*MAX(PL!J22,0) | K25: =-Assumptions!K46*MAX(PL!K22,0) | L25: =-Assumptions!L46*MAX(PL!L22,0) | M25: =-Assumptions!M46*MAX(PL!M22,0) | N25: =-Assumptions!N46*MAX(PL!N22,0) | O25: =-Assumptions!O46*MAX(PL!O22,0)
B26: Cash flow from financing activities | C26: =SUM(C21:C25) | D26: =SUM(D21:D25) | E26: =SUM(E21:E25) | F26: =SUM(F21:F25) | G26: =SUM(G21:G25) | H26: =SUM(H21:H25) | I26: =SUM(I21:I25) | J26: =SUM(J21:J25) | ... O26: =SUM(O21:O25)
B28: Net change in cash & investments | C28: =C30-C29 | D28: =D30-D29 | E28: =E30-E29 | F28: =F30-F29 | G28: =G30-G29 | H28: =H13+H19+H26 | I28: =I13+I19+I26 | J28: =J13+J19+J26 | K28: =K13+K19+K26 | L28: =L13+L19+L26 | M28: =M13+M19+M26 | N28: =N13+N19+N26 | O28: =O13+O19+O26
B29: Opening cash & investments | C29: 1343 | D29: 1477 | E29: 1260 | F29: 3726 | G29: 7400 | H29: =G30 | I29: =H30 | J29: =I30 | K29: =J30 | L29: =K30 | M29: =L30 | N29: =M30 | O29: =N30
B30: Closing cash & investments | C30: 1477 | D30: 1260 | E30: 3726 | F30: 7400 | G30: 4114 | H30: =H28+H29 | I30: =I28+I29 | J30: =J28+J29 | K30: =K28+K29 | L30: =L28+L29 | M30: =M28+M29 | N30: =N28+N29 | O30: =O28+O29

Sheet Working Capital Schedule
B2: Ather Energy Ltd — Working Capital Schedule (INR millions)
B4: Particulars | C4: 2021 | D4: =C4+1 | E4: =D4+1 | F4: =E4+1 | G4: =F4+1 | H4: =G4+1 | I4: =H4+1 | J4: =I4+1 | K4: =J4+1 | ... O4: =N4+1
B6: Revenue | C6: =PL!C5 | D6: =PL!D5 | E6: =PL!E5 | F6: =PL!F5 | G6: =PL!G5 | H6: =PL!H5 | I6: =PL!I5 | J6: =PL!J5 | ... O6: =PL!O5
B7: Cost of goods sold | C7: =-PL!C6 | D7: =-PL!D6 | E7: =-PL!E6 | F7: =-PL!F6 | G7: =-PL!G6 | H7: =-PL!H6 | I7: =-PL!I6 | J7: =-PL!J6 | ... O7: =-PL!O6
B9: Trade receivables | C9: =BS!C40 | D9: =BS!D40 | E9: =BS!E40 | F9: =BS!F40 | G9: =BS!G40 | H9: =(2*(H6*Assumptions!H50/365))-G9 | I9: =(2*(I6*Assumptions!I50/365))-H9 | J9: =(2*(J6*Assumptions!J50/365))-I9 | K9: =(2*(K6*Assumptions!K50/365))-J9 | L9: =(2*(L6*Assumptions!L50/365))-K9 | M9: =(2*(M6*Assumptions!M50/365))-L9 | N9: =(2*(N6*Assumptions!N50/365))-M9 | O9: =(2*(O6*Assumptions!O50/365))-N9
B10: Receivable days | D10: =AVERAGE(C9:D9)/D6*365 | E10: =AVERAGE(D9:E9)/E6*365 | F10: =AVERAGE(E9:F9)/F6*365 | G10: =AVERAGE(F9:G9)/G6*365 | H10: =AVERAGE(G9:H9)/H6*365 | I10: =AVERAGE(H9:I9)/I6*365 | J10: =AVERAGE(I9:J9)/J6*365 | K10: =AVERAGE(J9:K9)/K6*365 | ... O10: =AVERAGE(N9:O9)/O6*365
B12: Inventories | C12: =BS!C41 | D12: =BS!D41 | E12: =BS!E41 | F12: =BS!F41 | G12: =BS!G41 | H12: =(2*(H7*Assumptions!H51/365))-G12 | I12: =(2*(I7*Assumptions!I51/365))-H12 | J12: =(2*(J7*Assumptions!J51/365))-I12 | K12: =(2*(K7*Assumptions!K51/365))-J12 | L12: =(2*(L7*Assumptions!L51/365))-K12 | M12: =(2*(M7*Assumptions!M51/365))-L12 | N12: =(2*(N7*Assumptions!N51/365))-M12 | O12: =(2*(O7*Assumptions!O51/365))-N12
B13: Inventory days | D13: =AVERAGE(C12:D12)/D7*365 | E13: =AVERAGE(D12:E12)/E7*365 | F13: =AVERAGE(E12:F12)/F7*365 | G13: =AVERAGE(F12:G12)/G7*365 | H13: =AVERAGE(G12:H12)/H7*365 | I13: =AVERAGE(H12:I12)/I7*365 | J13: =AVERAGE(I12:J12)/J7*365 | K13: =AVERAGE(J12:K12)/K7*365 | ... O13: =AVERAGE(N12:O12)/O7*365
B15: Trade payables | C15: =BS!C20 | D15: =BS!D20 | E15: =BS!E20 | F15: =BS!F20 | G15: =BS!G20 | H15: =(2*(H7*Assumptions!H52/365))-G15 | I15: =(2*(I7*Assumptions!I52/365))-H15 | J15: =(2*(J7*Assumptions!J52/365))-I15 | K15: =(2*(K7*Assumptions!K52/365))-J15 | L15: =(2*(L7*Assumptions!L52/365))-K15 | M15: =(2*(M7*Assumptions!M52/365))-L15 | N15: =(2*(N7*Assumptions!N52/365))-M15 | O15: =(2*(O7*Assumptions!O52/365))-N15
B16: Payable days | D16: =AVERAGE(C15:D15)/D7*365 | E16: =AVERAGE(D15:E15)/E7*365 | F16: =AVERAGE(E15:F15)/F7*365 | G16: =AVERAGE(F15:G15)/G7*365 | H16: =AVERAGE(G15:H15)/H7*365 | I16: =AVERAGE(H15:I15)/I7*365 | J16: =AVERAGE(I15:J15)/J7*365 | K16: =AVERAGE(J15:K15)/K7*365 | ... O16: =AVERAGE(N15:O15)/O7*365
B18: Operating current assets (AR+Inv+Other CA) | C18: =BS!C40+BS!C41+BS!C42 | D18: =BS!D40+BS!D41+BS!D42 | E18: =BS!E40+BS!E41+BS!E42 | F18: =BS!F40+BS!F41+BS!F42 | G18: =BS!G40+BS!G41+BS!G42 | H18: =BS!H40+BS!H41+BS!H42 | I18: =BS!I40+BS!I41+BS!I42 | J18: =BS!J40+BS!J41+BS!J42 | ... O18: =BS!O40+BS!O41+BS!O42
B19: Operating current liabilities (Pay+Prov+Other CL) | C19: =BS!C20+BS!C23+BS!C24 | D19: =BS!D20+BS!D23+BS!D24 | E19: =BS!E20+BS!E23+BS!E24 | F19: =BS!F20+BS!F23+BS!F24 | G19: =BS!G20+BS!G23+BS!G24 | H19: =BS!H20+BS!H23+BS!H24 | I19: =BS!I20+BS!I23+BS!I24 | J19: =BS!J20+BS!J23+BS!J24 | ... O19: =BS!O20+BS!O23+BS!O24
B20: Net working capital | C20: =C18-C19 | D20: =D18-D19 | E20: =E18-E19 | F20: =F18-F19 | G20: =G18-G19 | H20: =H18-H19 | I20: =I18-I19 | J20: =J18-J19 | ... O20: =O18-O19
B21: Change in net working capital | D21: =D20-C20 | E21: =E20-D20 | F21: =F20-E20 | G21: =G20-F20 | H21: =H20-G20 | I21: =I20-H20 | J21: =J20-I20 | K21: =K20-J20 | ... O21: =O20-N20

Sheet Working Schedules
B2: Ather Energy Ltd — Supporting Schedules (INR millions)
B4: Property, Plant & Equipment Schedule (net block roll-forward)
B5: Particulars | C5: 2021 | D5: =C5+1 | E5: =D5+1 | F5: =E5+1 | G5: =F5+1 | H5: =G5+1 | I5: =H5+1 | J5: =I5+1 | K5: =J5+1 | ... O5: =N5+1
B6: Opening net block | H6: =G9 | I6: =H9 | J6: =I9 | K6: =J9 | L6: =K9 | M6: =L9 | N6: =M9 | O6: =N9
B7: Capex (PPE & CWIP) | H7: =PL!H5*Assumptions!H32 | I7: =PL!I5*Assumptions!I32 | J7: =PL!J5*Assumptions!J32 | K7: =PL!K5*Assumptions!K32 | L7: =PL!L5*Assumptions!L32 | M7: =PL!M5*Assumptions!M32 | N7: =PL!N5*Assumptions!N32 | O7: =PL!O5*Assumptions!O32
B8: Depreciation | H8: =-(H6+0.5*H7)/Assumptions!H33 | I8: =-(I6+0.5*I7)/Assumptions!I33 | J8: =-(J6+0.5*J7)/Assumptions!J33 | K8: =-(K6+0.5*K7)/Assumptions!K33 | L8: =-(L6+0.5*L7)/Assumptions!L33 | M8: =-(M6+0.5*M7)/Assumptions!M33 | N8: =-(N6+0.5*N7)/Assumptions!N33 | O8: =-(O6+0.5*O7)/Assumptions!O33
B9: Closing net block | G9: 2674 | H9: =H6+H7+H8 | I9: =I6+I7+I8 | J9: =J6+J7+J8 | K9: =K6+K7+K8 | L9: =L6+L7+L8 | M9: =M6+M7+M8 | N9: =N6+N7+N8 | O9: =O6+O7+O8
B11: Right-of-Use (Lease) Assets Schedule
B12: Particulars | C12: 2021 | D12: =C12+1 | E12: =D12+1 | F12: =E12+1 | G12: =F12+1 | H12: =G12+1 | I12: =H12+1 | J12: =I12+1 | K12: =J12+1 | ... O12: =N12+1
B13: Opening ROU assets | H13: =G16 | I13: =H16 | J13: =I16 | K13: =J16 | L13: =K16 | M13: =L16 | N13: =M16 | O13: =N16
B14: Additions (new leases) | H14: =PL!H5*Assumptions!H36 | I14: =PL!I5*Assumptions!I36 | J14: =PL!J5*Assumptions!J36 | K14: =PL!K5*Assumptions!K36 | L14: =PL!L5*Assumptions!L36 | M14: =PL!M5*Assumptions!M36 | N14: =PL!N5*Assumptions!N36 | O14: =PL!O5*Assumptions!O36
B15: Amortisation | H15: =-(H13+0.5*H14)*Assumptions!H37 | I15: =-(I13+0.5*I14)*Assumptions!I37 | J15: =-(J13+0.5*J14)*Assumptions!J37 | K15: =-(K13+0.5*K14)*Assumptions!K37 | L15: =-(L13+0.5*L14)*Assumptions!L37 | M15: =-(M13+0.5*M14)*Assumptions!M37 | N15: =-(N13+0.5*N14)*Assumptions!N37 | O15: =-(O13+0.5*O14)*Assumptions!O37
B16: Closing ROU assets | G16: 2443 | H16: =SUM(H13:H15) | I16: =SUM(I13:I15) | J16: =SUM(J13:J15) | K16: =SUM(K13:K15) | L16: =SUM(L13:L15) | M16: =SUM(M13:M15) | N16: =SUM(N13:N15) | O16: =SUM(O13:O15)
B18: Intangible Assets Schedule (incl. assets under development)
B19: Particulars | C19: 2021 | D19: =C19+1 | E19: =D19+1 | F19: =E19+1 | G19: =F19+1 | H19: =G19+1 | I19: =H19+1 | J19: =I19+1 | K19: =J19+1 | ... O19: =N19+1
B20: Opening intangibles | H20: =G23 | I20: =H23 | J20: =I23 | K20: =J23 | L20: =K23 | M20: =L23 | N20: =M23 | O20: =N23
B21: Additions (capitalised development) | H21: =PL!H5*Assumptions!H34 | I21: =PL!I5*Assumptions!I34 | J21: =PL!J5*Assumptions!J34 | K21: =PL!K5*Assumptions!K34 | L21: =PL!L5*Assumptions!L34 | M21: =PL!M5*Assumptions!M34 | N21: =PL!N5*Assumptions!N34 | O21: =PL!O5*Assumptions!O34
B22: Amortisation | H22: =-H20*Assumptions!H35 | I22: =-I20*Assumptions!I35 | J22: =-J20*Assumptions!J35 | K22: =-K20*Assumptions!K35 | L22: =-L20*Assumptions!L35 | M22: =-M20*Assumptions!M35 | N22: =-N20*Assumptions!N35 | O22: =-O20*Assumptions!O35
B23: Closing intangibles | G23: 2206 | H23: =SUM(H20:H22) | I23: =SUM(I20:I22) | J23: =SUM(J20:J22) | K23: =SUM(K20:K22) | L23: =SUM(L20:L22) | M23: =SUM(M20:M22) | N23: =SUM(N20:N22) | O23: =SUM(O20:O22)
B25: Capital Work-in-Progress
B26: Particulars | C26: 2021 | D26: =C26+1 | E26: =D26+1 | F26: =E26+1 | G26: =F26+1 | H26: =G26+1 | I26: =H26+1 | J26: =I26+1 | K26: =J26+1 | ... O26: =N26+1
B27: Capital work-in-progress (held) | G27: 57 | H27: =G27 | I27: =H27 | J27: =I27 | K27: =J27 | L27: =K27 | M27: =L27 | N27: =M27 | O27: =N27
B29: Total Depreciation & Amortisation
B30: Depreciation — PPE | H30: =H8 | I30: =I8 | J30: =J8 | K30: =K8 | L30: =L8 | M30: =M8 | N30: =N8 | O30: =O8
B31: Amortisation — ROU | H31: =H15 | I31: =I15 | J31: =J15 | K31: =K15 | L31: =L15 | M31: =M15 | N31: =N15 | O31: =O15
B32: Amortisation — intangibles | H32: =H22 | I32: =I22 | J32: =J22 | K32: =K22 | L32: =L22 | M32: =M22 | N32: =N22 | O32: =O22
B33: Total D&A (to P&L) | H33: =SUM(H30:H32) | I33: =SUM(I30:I32) | J33: =SUM(J30:J32) | K33: =SUM(K30:K32) | L33: =SUM(L30:L32) | M33: =SUM(M30:M32) | N33: =SUM(N30:N32) | O33: =SUM(O30:O32)
B35: Borrowings (Debt) Schedule
B36: Particulars | C36: 2021 | D36: =C36+1 | E36: =D36+1 | F36: =E36+1 | G36: =F36+1 | H36: =G36+1 | I36: =H36+1 | J36: =I36+1 | K36: =J36+1 | ... O36: =N36+1
B37: Opening borrowings | H37: =G39 | I37: =H39 | J37: =I39 | K37: =J39 | L37: =K39 | M37: =L39 | N37: =M39 | O37: =N39
B38: Net drawdown / (repayment) | H38: =Assumptions!H41 | I38: =Assumptions!I41 | J38: =Assumptions!J41 | K38: =Assumptions!K41 | L38: =Assumptions!L41 | M38: =Assumptions!M41 | N38: =Assumptions!N41 | O38: =Assumptions!O41
B39: Closing borrowings | G39: 4499 | H39: =H37+H38 | I39: =I37+I38 | J39: =J37+J38 | K39: =K37+K38 | L39: =L37+L38 | M39: =M37+M38 | N39: =N37+N38 | O39: =O37+O38
B40: Interest on borrowings | H40: =H37*Assumptions!H40 | I40: =I37*Assumptions!I40 | J40: =J37*Assumptions!J40 | K40: =K37*Assumptions!K40 | L40: =L37*Assumptions!L40 | M40: =M37*Assumptions!M40 | N40: =N37*Assumptions!N40 | O40: =O37*Assumptions!O40
B42: Lease Liability Schedule
B43: Particulars | C43: 2021 | D43: =C43+1 | E43: =D43+1 | F43: =E43+1 | G43: =F43+1 | H43: =G43+1 | I43: =H43+1 | J43: =I43+1 | K43: =J43+1 | ... O43: =N43+1
B44: Opening lease liability | H44: =G47 | I44: =H47 | J44: =I47 | K44: =J47 | L44: =K47 | M44: =L47 | N44: =M47 | O44: =N47
B45: Additions (new leases) | H45: =H14 | I45: =I14 | J45: =J14 | K45: =K14 | L45: =L14 | M45: =M14 | N45: =N14 | O45: =O14
B46: Principal repayment | G46: -211 | H46: =G46*(1+Assumptions!H43) | I46: =H46*(1+Assumptions!I43) | J46: =I46*(1+Assumptions!J43) | K46: =J46*(1+Assumptions!K43) | L46: =K46*(1+Assumptions!L43) | M46: =L46*(1+Assumptions!M43) | N46: =M46*(1+Assumptions!N43) | O46: =N46*(1+Assumptions!O43)
B47: Closing lease liability | G47: 1694 | H47: =H44+H45+H46 | I47: =I44+I45+I46 | J47: =J44+J45+J46 | K47: =K44+K45+K46 | L47: =L44+L45+L46 | M47: =M44+M45+M46 | N47: =N44+N45+N46 | O47: =O44+O45+O46
B48: Interest on lease liabilities | H48: =H44*Assumptions!H42 | I48: =I44*Assumptions!I42 | J48: =J44*Assumptions!J42 | K48: =K44*Assumptions!K42 | L48: =L44*Assumptions!L42 | M48: =M44*Assumptions!M42 | N48: =N44*Assumptions!N42 | O48: =O44*Assumptions!O42
...

Sheet Ratio Analysis
B2: Ather Energy Ltd — Ratio Analysis
B4: Particulars | C4: 2021 | D4: =C4+1 | E4: =D4+1 | F4: =E4+1 | G4: =F4+1 | H4: =G4+1 | I4: =H4+1 | J4: =I4+1 | K4: =J4+1 | ... O4: =N4+1
B5: Profitability
B6: Revenue growth % | D6: =PL!D5/PL!C5-1 | E6: =PL!E5/PL!D5-1 | F6: =PL!F5/PL!E5-1 | G6: =PL!G5/PL!F5-1 | H6: =PL!H5/PL!G5-1 | I6: =PL!I5/PL!H5-1 | J6: =PL!J5/PL!I5-1 | K6: =PL!K5/PL!J5-1 | ... O6: =PL!O5/PL!N5-1
B7: Gross margin % | C7: =PL!C7/PL!C5 | D7: =PL!D7/PL!D5 | E7: =PL!E7/PL!E5 | F7: =PL!F7/PL!F5 | G7: =PL!G7/PL!G5 | H7: =PL!H7/PL!H5 | I7: =PL!I7/PL!I5 | J7: =PL!J7/PL!J5 | ... O7: =PL!O7/PL!O5
B8: EBITDA margin % | C8: =PL!C12/PL!C5 | D8: =PL!D12/PL!D5 | E8: =PL!E12/PL!E5 | F8: =PL!F12/PL!F5 | G8: =PL!G12/PL!G5 | H8: =PL!H12/PL!H5 | I8: =PL!I12/PL!I5 | J8: =PL!J12/PL!J5 | ... O8: =PL!O12/PL!O5
B9: EBIT margin % | C9: =PL!C14/PL!C5 | D9: =PL!D14/PL!D5 | E9: =PL!E14/PL!E5 | F9: =PL!F14/PL!F5 | G9: =PL!G14/PL!G5 | H9: =PL!H14/PL!H5 | I9: =PL!I14/PL!I5 | J9: =PL!J14/PL!J5 | ... O9: =PL!O14/PL!O5
B10: Net profit margin % | C10: =PL!C22/PL!C5 | D10: =PL!D22/PL!D5 | E10: =PL!E22/PL!E5 | F10: =PL!F22/PL!F5 | G10: =PL!G22/PL!G5 | H10: =PL!H22/PL!H5 | I10: =PL!I22/PL!I5 | J10: =PL!J22/PL!J5 | ... O10: =PL!O22/PL!O5
B11: Return on equity (ROE) % | D11: =PL!D22/AVERAGE(BS!C10,BS!D10) | E11: =PL!E22/AVERAGE(BS!D10,BS!E10) | F11: =PL!F22/AVERAGE(BS!E10,BS!F10) | G11: =PL!G22/AVERAGE(BS!F10,BS!G10) | H11: =PL!H22/AVERAGE(BS!G10,BS!H10) | I11: =PL!I22/AVERAGE(BS!H10,BS!I10) | J11: =PL!J22/AVERAGE(BS!I10,BS!J10) | K11: =PL!K22/AVERAGE(BS!J10,BS!K10) | ... O11: =PL!O22/AVERAGE(BS!N10,BS!O10)
B12: Return on capital employed (ROCE) % | C12: =PL!C14/(BS!C46-BS!C25) | D12: =PL!D14/(BS!D46-BS!D25) | E12: =PL!E14/(BS!E46-BS!E25) | F12: =PL!F14/(BS!F46-BS!F25) | G12: =PL!G14/(BS!G46-BS!G25) | H12: =PL!H14/(BS!H46-BS!H25) | I12: =PL!I14/(BS!I46-BS!I25) | J12: =PL!J14/(BS!J46-BS!J25) | ... O12: =PL!O14/(BS!O46-BS!O25)
B13: Return on invested capital (ROIC) % | C13: =PL!C14/(BS!C10+BS!C13+BS!C21+BS!C14+BS!C22) | D13: =PL!D14/(BS!D10+BS!D13+BS!D21+BS!D14+BS!D22) | E13: =PL!E14/(BS!E10+BS!E13+BS!E21+BS!E14+BS!E22) | F13: =PL!F14/(BS!F10+BS!F13+BS!F21+BS!F14+BS!F22) | G13: =PL!G14/(BS!G10+BS!G13+BS!G21+BS!G14+BS!G22) | H13: =PL!H14/(BS!H10+BS!H13+BS!H21+BS!H14+BS!H22) | I13: =PL!I14/(BS!I10+BS!I13+BS!I21+BS!I14+BS!I22) | J13: =PL!J14/(BS!J10+BS!J13+BS!J21+BS!J14+BS!J22) | ... O13: =PL!O14/(BS!O10+BS!O13+BS!O21+BS!O14+BS!O22)
B15: Liquidity & Solvency
B16: Current ratio | C16: =BS!C44/BS!C25 | D16: =BS!D44/BS!D25 | E16: =BS!E44/BS!E25 | F16: =BS!F44/BS!F25 | G16: =BS!G44/BS!G25 | H16: =BS!H44/BS!H25 | I16: =BS!I44/BS!I25 | J16: =BS!J44/BS!J25 | ... O16: =BS!O44/BS!O25
B17: Quick ratio | C17: =(BS!C44-BS!C41)/BS!C25 | D17: =(BS!D44-BS!D41)/BS!D25 | E17: =(BS!E44-BS!E41)/BS!E25 | F17: =(BS!F44-BS!F41)/BS!F25 | G17: =(BS!G44-BS!G41)/BS!G25 | H17: =(BS!H44-BS!H41)/BS!H25 | I17: =(BS!I44-BS!I41)/BS!I25 | J17: =(BS!J44-BS!J41)/BS!J25 | ... O17: =(BS!O44-BS!O41)/BS!O25
B18: Debt-to-equity (incl. leases) | C18: =(BS!C13+BS!C21+BS!C14+BS!C22)/BS!C10 | D18: =(BS!D13+BS!D21+BS!D14+BS!D22)/BS!D10 | E18: =(BS!E13+BS!E21+BS!E14+BS!E22)/BS!E10 | F18: =(BS!F13+BS!F21+BS!F14+BS!F22)/BS!F10 | G18: =(BS!G13+BS!G21+BS!G14+BS!G22)/BS!G10 | H18: =(BS!H13+BS!H21+BS!H14+BS!H22)/BS!H10 | I18: =(BS!I13+BS!I21+BS!I14+BS!I22)/BS!I10 | J18: =(BS!J13+BS!J21+BS!J14+BS!J22)/BS!J10 | ... O18: =(BS!O13+BS!O21+BS!O14+BS!O22)/BS!O10
B19: Net debt / EBITDA | C19: =(BS!C13+BS!C21+BS!C14+BS!C22-BS!C43)/PL!C12 | D19: =(BS!D13+BS!D21+BS!D14+BS!D22-BS!D43)/PL!D12 | E19: =(BS!E13+BS!E21+BS!E14+BS!E22-BS!E43)/PL!E12 | F19: =(BS!F13+BS!F21+BS!F14+BS!F22-BS!F43)/PL!F12 | G19: =(BS!G13+BS!G21+BS!G14+BS!G22-BS!G43)/PL!G12 | H19: =(BS!H13+BS!H21+BS!H14+BS!H22-BS!H43)/PL!H12 | I19: =(BS!I13+BS!I21+BS!I14+BS!I22-BS!I43)/PL!I12 | J19: =(BS!J13+BS!J21+BS!J14+BS!J22-BS!J43)/PL!J12 | ... O19: =(BS!O13+BS!O21+BS!O14+BS!O22-BS!O43)/PL!O12
B20: Interest coverage (EBIT/Interest) | C20: =PL!C14/-PL!C17 | D20: =PL!D14/-PL!D17 | E20: =PL!E14/-PL!E17 | F20: =PL!F14/-PL!F17 | G20: =PL!G14/-PL!G17 | H20: =PL!H14/-PL!H17 | I20: =PL!I14/-PL!I17 | J20: =PL!J14/-PL!J17 | ... O20: =PL!O14/-PL!O17
B22: Efficiency / Working Capital
B23: Asset turnover (x) | D23: =PL!D5/AVERAGE(BS!C46,BS!D46) | E23: =PL!E5/AVERAGE(BS!D46,BS!E46) | F23: =PL!F5/AVERAGE(BS!E46,BS!F46) | G23: =PL!G5/AVERAGE(BS!F46,BS!G46) | H23: =PL!H5/AVERAGE(BS!G46,BS!H46) | I23: =PL!I5/AVERAGE(BS!H46,BS!I46) | J23: =PL!J5/AVERAGE(BS!I46,BS!J46) | K23: =PL!K5/AVERAGE(BS!J46,BS!K46) | ... O23: =PL!O5/AVERAGE(BS!N46,BS!O46)
B24: Fixed-asset turnover (x) | D24: =PL!D5/AVERAGE(BS!C35,BS!D35) | E24: =PL!E5/AVERAGE(BS!D35,BS!E35) | F24: =PL!F5/AVERAGE(BS!E35,BS!F35) | G24: =PL!G5/AVERAGE(BS!F35,BS!G35) | H24: =PL!H5/AVERAGE(BS!G35,BS!H35) | I24: =PL!I5/AVERAGE(BS!H35,BS!I35) | J24: =PL!J5/AVERAGE(BS!I35,BS!J35) | K24: =PL!K5/AVERAGE(BS!J35,BS!K35) | ... O24: =PL!O5/AVERAGE(BS!N35,BS!O35)
B25: Receivable days | D25: ='Working Capital Schedule'!D10 | E25: ='Working Capital Schedule'!E10 | F25: ='Working Capital Schedule'!F10 | G25: ='Working Capital Schedule'!G10 | H25: ='Working Capital Schedule'!H10 | I25: ='Working Capital Schedule'!I10 | J25: ='Working Capital Schedule'!J10 | K25: ='Working Capital Schedule'!K10 | ... O25: ='Working Capital Schedule'!O10
B26: Inventory days | D26: ='Working Capital Schedule'!D13 | E26: ='Working Capital Schedule'!E13 | F26: ='Working Capital Schedule'!F13 | G26: ='Working Capital Schedule'!G13 | H26: ='Working Capital Schedule'!H13 | I26: ='Working Capital Schedule'!I13 | J26: ='Working Capital Schedule'!J13 | K26: ='Working Capital Schedule'!K13 | ... O26: ='Working Capital Schedule'!O13
B27: Payable days | D27: ='Working Capital Schedule'!D16 | E27: ='Working Capital Schedule'!E16 | F27: ='Working Capital Schedule'!F16 | G27: ='Working Capital Schedule'!G16 | H27: ='Working Capital Schedule'!H16 | I27: ='Working Capital Schedule'!I16 | J27: ='Working Capital Schedule'!J16 | K27: ='Working Capital Schedule'!K16 | ... O27: ='Working Capital Schedule'!O16
B28: Cash conversion cycle (days) | D28: ='Working Capital Schedule'!D10+'Working Capital Schedule'!D13-'Working Capital Schedule'!D16 | E28: ='Working Capital Schedule'!E10+'Working Capital Schedule'!E13-'Working Capital Schedule'!E16 | F28: ='Working Capital Schedule'!F10+'Working Capital Schedule'!F13-'Working Capital Schedule'!F16 | G28: ='Working Capital Schedule'!G10+'Working Capital Schedule'!G13-'Working Capital Schedule'!G16 | H28: ='Working Capital Schedule'!H10+'Working Capital Schedule'!H13-'Working Capital Schedule'!H16 | I28: ='Working Capital Schedule'!I10+'Working Capital Schedule'!I13-'Working Capital Schedule'!I16 | J28: ='Working Capital Schedule'!J10+'Working Capital Schedule'!J13-'Working Capital Schedule'!J16 | K28: ='Working Capital Schedule'!K10+'Working Capital Schedule'!K13-'Working Capital Schedule'!K16 | ... O28: ='Working Capital Schedule'!O10+'Working Capital Schedule'!O13-'Working Capital Schedule'!O16
B30: Cash Flow & Per-share
B31: CFO / Revenue % | C31: =CS!C13/PL!C5 | D31: =CS!D13/PL!D5 | E31: =CS!E13/PL!E5 | F31: =CS!F13/PL!F5 | G31: =CS!G13/PL!G5 | H31: =CS!H13/PL!H5 | I31: =CS!I13/PL!I5 | J31: =CS!J13/PL!J5 | ... O31: =CS!O13/PL!O5
B32: Free cash flow (INR m) | C32: =CS!C13+CS!C16+CS!C17 | D32: =CS!D13+CS!D16+CS!D17 | E32: =CS!E13+CS!E16+CS!E17 | F32: =CS!F13+CS!F16+CS!F17 | G32: =CS!G13+CS!G16+CS!G17 | H32: =CS!H13+CS!H16+CS!H17 | I32: =CS!I13+CS!I16+CS!I17 | J32: =CS!J13+CS!J16+CS!J17 | ... O32: =CS!O13+CS!O16+CS!O17
B34: Shares outstanding (m) | C34: 290.6 | D34: 290.6 | E34: 290.6 | F34: 290.6 | G34: 290.6 | H34: 372 | I34: 372 | J34: 372 | K34: 372 | L34: 372 | M34: 372 | N34: 372 | O34: 372
B35: EPS (INR) | C35: =PL!C22/C34 | D35: =PL!D22/D34 | E35: =PL!E22/E34 | F35: =PL!F22/F34 | G35: =PL!G22/G34 | H35: =PL!H22/H34 | I35: =PL!I22/I34 | J35: =PL!J22/J34 | ... O35: =PL!O22/O34

Sheet Error Checks
B2: Ather Energy Ltd — Integrity & Error Checks
B3: Every check should read PASS. Tolerance = 0.5 (INR m).
B4: Particulars | C4: 2021 | D4: =C4+1 | E4: =D4+1 | F4: =E4+1 | G4: =F4+1 | H4: =G4+1 | I4: =H4+1 | J4: =I4+1 | K4: =J4+1 | ... O4: =N4+1
B5: Balance sheet integrity
B6: Balance sheet balances (Assets = Equity + Liab.) | C6: =IF(ABS(BS!C48)<0.5,"PASS","FAIL") | D6: =IF(ABS(BS!D48)<0.5,"PASS","FAIL") | E6: =IF(ABS(BS!E48)<0.5,"PASS","FAIL") | F6: =IF(ABS(BS!F48)<0.5,"PASS","FAIL") | G6: =IF(ABS(BS!G48)<0.5,"PASS","FAIL") | H6: =IF(ABS(BS!H48)<0.5,"PASS","FAIL") | I6: =IF(ABS(BS!I48)<0.5,"PASS","FAIL") | J6: =IF(ABS(BS!J48)<0.5,"PASS","FAIL") | ... O6: =IF(ABS(BS!O48)<0.5,"PASS","FAIL")
B7: Total assets reconcile (NCA + CA) | C7: =IF(ABS(BS!C46-BS!C37-BS!C44)<0.5,"PASS","FAIL") | D7: =IF(ABS(BS!D46-BS!D37-BS!D44)<0.5,"PASS","FAIL") | E7: =IF(ABS(BS!E46-BS!E37-BS!E44)<0.5,"PASS","FAIL") | F7: =IF(ABS(BS!F46-BS!F37-BS!F44)<0.5,"PASS","FAIL") | G7: =IF(ABS(BS!G46-BS!G37-BS!G44)<0.5,"PASS","FAIL") | H7: =IF(ABS(BS!H46-BS!H37-BS!H44)<0.5,"PASS","FAIL") | I7: =IF(ABS(BS!I46-BS!I37-BS!I44)<0.5,"PASS","FAIL") | J7: =IF(ABS(BS!J46-BS!J37-BS!J44)<0.5,"PASS","FAIL") | ... O7: =IF(ABS(BS!O46-BS!O37-BS!O44)<0.5,"PASS","FAIL")
B9: Cash flow integrity
B10: BS cash = Cash-flow closing cash | C10: =IF(ABS(BS!C43-CS!C30)<0.5,"PASS","FAIL") | D10: =IF(ABS(BS!D43-CS!D30)<0.5,"PASS","FAIL") | E10: =IF(ABS(BS!E43-CS!E30)<0.5,"PASS","FAIL") | F10: =IF(ABS(BS!F43-CS!F30)<0.5,"PASS","FAIL") | G10: =IF(ABS(BS!G43-CS!G30)<0.5,"PASS","FAIL") | H10: =IF(ABS(BS!H43-CS!H30)<0.5,"PASS","FAIL") | I10: =IF(ABS(BS!I43-CS!I30)<0.5,"PASS","FAIL") | J10: =IF(ABS(BS!J43-CS!J30)<0.5,"PASS","FAIL") | ... O10: =IF(ABS(BS!O43-CS!O30)<0.5,"PASS","FAIL")
B11: Opening cash (t) = Closing cash (t-1) | D11: =IF(ABS(CS!D29-CS!C30)<0.5,"PASS","FAIL") | E11: =IF(ABS(CS!E29-CS!D30)<0.5,"PASS","FAIL") | F11: =IF(ABS(CS!F29-CS!E30)<0.5,"PASS","FAIL") | G11: =IF(ABS(CS!G29-CS!F30)<0.5,"PASS","FAIL") | H11: =IF(ABS(CS!H29-CS!G30)<0.5,"PASS","FAIL") | I11: =IF(ABS(CS!I29-CS!H30)<0.5,"PASS","FAIL") | J11: =IF(ABS(CS!J29-CS!I30)<0.5,"PASS","FAIL") | K11: =IF(ABS(CS!K29-CS!J30)<0.5,"PASS","FAIL") | ... O11: =IF(ABS(CS!O29-CS!N30)<0.5,"PASS","FAIL")
B12: Cash balance non-negative | C12: =IF(BS!C43>=-0.5,"PASS","FAIL") | D12: =IF(BS!D43>=-0.5,"PASS","FAIL") | E12: =IF(BS!E43>=-0.5,"PASS","FAIL") | F12: =IF(BS!F43>=-0.5,"PASS","FAIL") | G12: =IF(BS!G43>=-0.5,"PASS","FAIL") | H12: =IF(BS!H43>=-0.5,"PASS","FAIL") | I12: =IF(BS!I43>=-0.5,"PASS","FAIL") | J12: =IF(BS!J43>=-0.5,"PASS","FAIL") | ... O12: =IF(BS!O43>=-0.5,"PASS","FAIL")
B14: Roll-forward checks (forecast)
B15: Borrowings roll-forward (close = open + net) | H15: =IF(ABS('Working Schedules'!H39-'Working Schedules'!H37-'Working Schedules'!H38)<0.5,"PASS","FAIL") | I15: =IF(ABS('Working Schedules'!I39-'Working Schedules'!I37-'Working Schedules'!I38)<0.5,"PASS","FAIL") | J15: =IF(ABS('Working Schedules'!J39-'Working Schedules'!J37-'Working Schedules'!J38)<0.5,"PASS","FAIL") | K15: =IF(ABS('Working Schedules'!K39-'Working Schedules'!K37-'Working Schedules'!K38)<0.5,"PASS","FAIL") | L15: =IF(ABS('Working Schedules'!L39-'Working Schedules'!L37-'Working Schedules'!L38)<0.5,"PASS","FAIL") | M15: =IF(ABS('Working Schedules'!M39-'Working Schedules'!M37-'Working Schedules'!M38)<0.5,"PASS","FAIL") | N15: =IF(ABS('Working Schedules'!N39-'Working Schedules'!N37-'Working Schedules'!N38)<0.5,"PASS","FAIL") | O15: =IF(ABS('Working Schedules'!O39-'Working Schedules'!O37-'Working Schedules'!O38)<0.5,"PASS","FAIL")
B16: PPE roll-forward (close = open + capex + dep) | H16: =IF(ABS('Working Schedules'!H9-'Working Schedules'!H6-'Working Schedules'!H7-'Working Schedules'!H8)<0.5,"PASS","FAIL") | I16: =IF(ABS('Working Schedules'!I9-'Working Schedules'!I6-'Working Schedules'!I7-'Working Schedules'!I8)<0.5,"PASS","FAIL") | J16: =IF(ABS('Working Schedules'!J9-'Working Schedules'!J6-'Working Schedules'!J7-'Working Schedules'!J8)<0.5,"PASS","FAIL") | K16: =IF(ABS('Working Schedules'!K9-'Working Schedules'!K6-'Working Schedules'!K7-'Working Schedules'!K8)<0.5,"PASS","FAIL") | L16: =IF(ABS('Working Schedules'!L9-'Working Schedules'!L6-'Working Schedules'!L7-'Working Schedules'!L8)<0.5,"PASS","FAIL") | M16: =IF(ABS('Working Schedules'!M9-'Working Schedules'!M6-'Working Schedules'!M7-'Working Schedules'!M8)<0.5,"PASS","FAIL") | N16: =IF(ABS('Working Schedules'!N9-'Working Schedules'!N6-'Working Schedules'!N7-'Working Schedules'!N8)<0.5,"PASS","FAIL") | O16: =IF(ABS('Working Schedules'!O9-'Working Schedules'!O6-'Working Schedules'!O7-'Working Schedules'!O8)<0.5,"PASS","FAIL")
B17: Lease roll-forward (close = open + add + repay) | H17: =IF(ABS('Working Schedules'!H47-'Working Schedules'!H44-'Working Schedules'!H45-'Working Schedules'!H46)<0.5,"PASS","FAIL") | I17: =IF(ABS('Working Schedules'!I47-'Working Schedules'!I44-'Working Schedules'!I45-'Working Schedules'!I46)<0.5,"PASS","FAIL") | J17: =IF(ABS('Working Schedules'!J47-'Working Schedules'!J44-'Working Schedules'!J45-'Working Schedules'!J46)<0.5,"PASS","FAIL") | K17: =IF(ABS('Working Schedules'!K47-'Working Schedules'!K44-'Working Schedules'!K45-'Working Schedules'!K46)<0.5,"PASS","FAIL") | L17: =IF(ABS('Working Schedules'!L47-'Working Schedules'!L44-'Working Schedules'!L45-'Working Schedules'!L46)<0.5,"PASS","FAIL") | M17: =IF(ABS('Working Schedules'!M47-'Working Schedules'!M44-'Working Schedules'!M45-'Working Schedules'!M46)<0.5,"PASS","FAIL") | N17: =IF(ABS('Working Schedules'!N47-'Working Schedules'!N44-'Working Schedules'!N45-'Working Schedules'!N46)<0.5,"PASS","FAIL") | O17: =IF(ABS('Working Schedules'!O47-'Working Schedules'!O44-'Working Schedules'!O45-'Working Schedules'!O46)<0.5,"PASS","FAIL")
